============================= test session starts ==============================
platform linux -- Python 3.12.3, pytest-8.4.1, pluggy-1.6.0
rootdir: /app
configfile: pytest.ini
collected 10 items / 11 errors
INTERNALERROR> Traceback (most recent call last):
INTERNALERROR>   File "/app/tests/triangulum_agent_test.py", line 46, in <module>
INTERNALERROR>     from triangulum_lx.agents.enhanced_message_bus import EnhancedMessageBus
INTERNALERROR>   File "/app/triangulum_lx/agents/__init__.py", line 6, in <module>
INTERNALERROR>     from .response_cache import ResponseCache, get_response_cache
INTERNALERROR>   File "/app/triangulum_lx/agents/response_cache.py", line 15, in <module>
INTERNALERROR>     from ..providers.base import LLMResponse
INTERNALERROR>   File "/app/triangulum_lx/providers/__init__.py", line 10, in <module>
INTERNALERROR>     from .openai import OpenAIProvider
INTERNALERROR>   File "/app/triangulum_lx/providers/openai.py", line 11, in <module>
INTERNALERROR>     from openai import OpenAI
INTERNALERROR> ModuleNotFoundError: No module named 'openai'
INTERNALERROR>
INTERNALERROR> During handling of the above exception, another exception occurred:
INTERNALERROR>
INTERNALERROR> Traceback (most recent call last):
INTERNALERROR>   File "/home/jules/.local/share/pipx/venvs/pytest/lib/python3.12/site-packages/_pytest/main.py", line 289, in wrap_session
INTERNALERROR>     session.exitstatus = doit(config, session) or 0
INTERNALERROR>                          ^^^^^^^^^^^^^^^^^^^^^
INTERNALERROR>   File "/home/jules/.local/share/pipx/venvs/pytest/lib/python3.12/site-packages/_pytest/main.py", line 342, in _main
INTERNALERROR>     config.hook.pytest_collection(session=session)
INTERNALERROR>   File "/home/jules/.local/share/pipx/venvs/pytest/lib/python3.12/site-packages/pluggy/_hooks.py", line 512, in __call__
INTERNALERROR>     return self._hookexec(self.name, self._hookimpls.copy(), kwargs, firstresult)
INTERNALERROR>            ^^^^^^^^^^^^^^^^^^^^^^^^^^^^^^^^^^^^^^^^^^^^^^^^^^^^^^^^^^^^^^^^^^^^^^
INTERNALERROR>   File "/home/jules/.local/share/pipx/venvs/pytest/lib/python3.12/site-packages/pluggy/_manager.py", line 120, in _hookexec
INTERNALERROR>     return self._inner_hookexec(hook_name, methods, kwargs, firstresult)
INTERNALERROR>            ^^^^^^^^^^^^^^^^^^^^^^^^^^^^^^^^^^^^^^^^^^^^^^^^^^^^^^^^^^^^^
INTERNALERROR>   File "/home/jules/.local/share/pipx/venvs/pytest/lib/python3.12/site-packages/pluggy/_callers.py", line 167, in _multicall
INTERNALERROR>     raise exception
INTERNALERROR>   File "/home/jules/.local/share/pipx/venvs/pytest/lib/python3.12/site-packages/pluggy/_callers.py", line 139, in _multicall
INTERNALERROR>     teardown.throw(exception)
INTERNALERROR>   File "/home/jules/.local/share/pipx/venvs/pytest/lib/python3.12/site-packages/_pytest/logging.py", line 788, in pytest_collection
INTERNALERROR>     return (yield)
INTERNALERROR>             ^^^^^
INTERNALERROR>   File "/home/jules/.local/share/pipx/venvs/pytest/lib/python3.12/site-packages/pluggy/_callers.py", line 139, in _multicall
INTERNALERROR>     teardown.throw(exception)
INTERNALERROR>   File "/home/jules/.local/share/pipx/venvs/pytest/lib/python3.12/site-packages/_pytest/warnings.py", line 99, in pytest_collection
INTERNALERROR>     return (yield)
INTERNALERROR>             ^^^^^
INTERNALERROR>   File "/home/jules/.local/share/pipx/venvs/pytest/lib/python3.12/site-packages/pluggy/_callers.py", line 139, in _multicall
INTERNALERROR>     teardown.throw(exception)
INTERNALERROR>   File "/home/jules/.local/share/pipx/venvs/pytest/lib/python3.12/site-packages/_pytest/config/__init__.py", line 1450, in pytest_collection
INTERNALERROR>     return (yield)
INTERNALERROR>             ^^^^^
INTERNALERROR>   File "/home/jules/.local/share/pipx/venvs/pytest/lib/python3.12/site-packages/pluggy/_callers.py", line 121, in _multicall
INTERNALERROR>     res = hook_impl.function(*args)
INTERNALERROR>           ^^^^^^^^^^^^^^^^^^^^^^^^^
INTERNALERROR>   File "/home/jules/.local/share/pipx/venvs/pytest/lib/python3.12/site-packages/_pytest/main.py", line 353, in pytest_collection
INTERNALERROR>     session.perform_collect()
INTERNALERROR>   File "/home/jules/.local/share/pipx/venvs/pytest/lib/python3.12/site-packages/_pytest/main.py", line 813, in perform_collect
INTERNALERROR>     self.items.extend(self.genitems(node))
INTERNALERROR>   File "/home/jules/.local/share/pipx/venvs/pytest/lib/python3.12/site-packages/_pytest/main.py", line 979, in genitems
INTERNALERROR>     yield from self.genitems(subnode)
INTERNALERROR>   File "/home/jules/.local/share/pipx/venvs/pytest/lib/python3.12/site-packages/_pytest/main.py", line 979, in genitems
INTERNALERROR>     yield from self.genitems(subnode)
INTERNALERROR>   File "/home/jules/.local/share/pipx/venvs/pytest/lib/python3.12/site-packages/_pytest/main.py", line 974, in genitems
INTERNALERROR>     rep, duplicate = self._collect_one_node(node, handle_dupes)
INTERNALERROR>                      ^^^^^^^^^^^^^^^^^^^^^^^^^^^^^^^^^^^^^^^^^^
INTERNALERROR>   File "/home/jules/.local/share/pipx/venvs/pytest/lib/python3.12/site-packages/_pytest/main.py", line 839, in _collect_one_node
INTERNALERROR>     rep = collect_one_node(node)
INTERNALERROR>           ^^^^^^^^^^^^^^^^^^^^^^
INTERNALERROR>   File "/home/jules/.local/share/pipx/venvs/pytest/lib/python3.12/site-packages/_pytest/runner.py", line 567, in collect_one_node
INTERNALERROR>     rep: CollectReport = ihook.pytest_make_collect_report(collector=collector)
INTERNALERROR>                          ^^^^^^^^^^^^^^^^^^^^^^^^^^^^^^^^^^^^^^^^^^^^^^^^^^^^^
INTERNALERROR>   File "/home/jules/.local/share/pipx/venvs/pytest/lib/python3.12/site-packages/pluggy/_hooks.py", line 512, in __call__
INTERNALERROR>     return self._hookexec(self.name, self._hookimpls.copy(), kwargs, firstresult)
INTERNALERROR>            ^^^^^^^^^^^^^^^^^^^^^^^^^^^^^^^^^^^^^^^^^^^^^^^^^^^^^^^^^^^^^^^^^^^^^^
INTERNALERROR>   File "/home/jules/.local/share/pipx/venvs/pytest/lib/python3.12/site-packages/pluggy/_manager.py", line 120, in _hookexec
INTERNALERROR>     return self._inner_hookexec(hook_name, methods, kwargs, firstresult)
INTERNALERROR>            ^^^^^^^^^^^^^^^^^^^^^^^^^^^^^^^^^^^^^^^^^^^^^^^^^^^^^^^^^^^^^
INTERNALERROR>   File "/home/jules/.local/share/pipx/venvs/pytest/lib/python3.12/site-packages/pluggy/_callers.py", line 167, in _multicall
INTERNALERROR>     raise exception
INTERNALERROR>   File "/home/jules/.local/share/pipx/venvs/pytest/lib/python3.12/site-packages/pluggy/_callers.py", line 139, in _multicall
INTERNALERROR>     teardown.throw(exception)
INTERNALERROR>   File "/home/jules/.local/share/pipx/venvs/pytest/lib/python3.12/site-packages/_pytest/capture.py", line 880, in pytest_make_collect_report
INTERNALERROR>     rep = yield
INTERNALERROR>           ^^^^^
INTERNALERROR>   File "/home/jules/.local/share/pipx/venvs/pytest/lib/python3.12/site-packages/pluggy/_callers.py", line 121, in _multicall
INTERNALERROR>     res = hook_impl.function(*args)
INTERNALERROR>           ^^^^^^^^^^^^^^^^^^^^^^^^^
INTERNALERROR>   File "/home/jules/.local/share/pipx/venvs/pytest/lib/python3.12/site-packages/_pytest/runner.py", line 391, in pytest_make_collect_report
INTERNALERROR>     call = CallInfo.from_call(
INTERNALERROR>            ^^^^^^^^^^^^^^^^^^^
INTERNALERROR>   File "/home/jules/.local/share/pipx/venvs/pytest/lib/python3.12/site-packages/_pytest/runner.py", line 344, in from_call
INTERNALERROR>     result: TResult | None = func()
INTERNALERROR>                              ^^^^^^
INTERNALERROR>   File "/home/jules/.local/share/pipx/venvs/pytest/lib/python3.12/site-packages/_pytest/runner.py", line 389, in collect
INTERNALERROR>     return list(collector.collect())
INTERNALERROR>                 ^^^^^^^^^^^^^^^^^^^
INTERNALERROR>   File "/home/jules/.local/share/pipx/venvs/pytest/lib/python3.12/site-packages/_pytest/python.py", line 554, in collect
INTERNALERROR>     self._register_setup_module_fixture()
INTERNALERROR>   File "/home/jules/.local/share/pipx/venvs/pytest/lib/python3.12/site-packages/_pytest/python.py", line 567, in _register_setup_module_fixture
mainloop: caught unexpected SystemExit!
INTERNALERROR>     self.obj, ("setUpModule", "setup_module")
INTERNALERROR>     ^^^^^^^^
INTERNALERROR>   File "/home/jules/.local/share/pipx/venvs/pytest/lib/python3.12/site-packages/_pytest/python.py", line 280, in obj
INTERNALERROR>     self._obj = obj = self._getobj()
INTERNALERROR>                       ^^^^^^^^^^^^^^
INTERNALERROR>   File "/home/jules/.local/share/pipx/venvs/pytest/lib/python3.12/site-packages/_pytest/python.py", line 551, in _getobj
INTERNALERROR>     return importtestmodule(self.path, self.config)
INTERNALERROR>            ^^^^^^^^^^^^^^^^^^^^^^^^^^^^^^^^^^^^^^^^
INTERNALERROR>   File "/home/jules/.local/share/pipx/venvs/pytest/lib/python3.12/site-packages/_pytest/python.py", line 498, in importtestmodule
INTERNALERROR>     mod = import_path(
INTERNALERROR>           ^^^^^^^^^^^^
INTERNALERROR>   File "/home/jules/.local/share/pipx/venvs/pytest/lib/python3.12/site-packages/_pytest/pathlib.py", line 587, in import_path
INTERNALERROR>     importlib.import_module(module_name)
INTERNALERROR>   File "/usr/lib/python3.12/importlib/__init__.py", line 90, in import_module
INTERNALERROR>     return _bootstrap._gcd_import(name[level:], package, level)
INTERNALERROR>            ^^^^^^^^^^^^^^^^^^^^^^^^^^^^^^^^^^^^^^^^^^^^^^^^^^^^
INTERNALERROR>   File "<frozen importlib._bootstrap>", line 1387, in _gcd_import
INTERNALERROR>   File "<frozen importlib._bootstrap>", line 1360, in _find_and_load
INTERNALERROR>   File "<frozen importlib._bootstrap>", line 1331, in _find_and_load_unlocked
INTERNALERROR>   File "<frozen importlib._bootstrap>", line 935, in _load_unlocked
INTERNALERROR>   File "/home/jules/.local/share/pipx/venvs/pytest/lib/python3.12/site-packages/_pytest/assertion/rewrite.py", line 186, in exec_module
INTERNALERROR>     exec(co, module.__dict__)
INTERNALERROR>   File "/app/tests/triangulum_agent_test.py", line 57, in <module>
INTERNALERROR>     sys.exit(1)
INTERNALERROR> SystemExit: 1

======================== 1 warning, 11 errors in 0.74s =========================
