# Triangulum Debug Session: test_bug.py

- **Time**: 2025-06-30 17:55:57
- **Description**: Unknown bug
- **Error**: None

## Code Relationship Context

```
Code Relationship Analysis for test_bug.py:
```

## Debug Output

```

=== Starting debug cycle for Bug #1 (WAIT): Unknown bug ===

Coordinator Initial Assessment:
ACTION: Direct the Observer agent to perform an initial analysis of the code to identify any potential issues.

RESULT: The current state of the bug is "WAIT" with an "Unknown bug" description, and there are no previous agent actions to guide us. The code provided includes a division operation that explicitly handles division by zero by returning an error message. However, the bug is marked as "unknown," suggesting there might be more to uncover. The Observer agent is best suited to perform an initial analysis to identify any issues or confirm the presence of a bug. Once the Observer provides insights, we can decide on the next steps based on their findings.


--> Next agent: observer

Observer Agent Output:
ACTION: Analyze the provided code to identify potential bugs or error conditions.

RESULT: Upon reviewing the code, the primary issue is related to the handling of division by zero. The `divide` function correctly checks for division by zero and returns an error message string when `b` is zero. However, this error handling approach does not raise an exception, which means the `except` block in the `main` function will not be executed. Instead, the error message is simply returned as a string and printed as part of the result.

To improve the error handling and ensure the `except` block is utilized, the `divide` function should raise an exception when a division by zero is detected. This can be done using Python's built-in `ZeroDivisionError`. Here is a suggested modification:

```python
def divide(a, b):
    if b == 0:
        raise ZeroDivisionError("Division by zero is not allowed.")
    return a / b
```

With this change, the `except` block in the `main` function will catch the `ZeroDivisionError`, and the error message will be printed as intended.

No other significant issues were identified in the code. The primary concern is the handling of division by zero, which can be addressed by raising an exception as described above.


--> Next agent: observer

Observer Agent Output:
ACTION: Analyze the provided code to identify any potential bugs or error conditions.

RESULT: The primary issue in the code is related to how division by zero is handled in the `divide` function. Currently, the function returns a string error message when `b` is zero, which is not ideal because it bypasses the exception handling mechanism in the `main` function. This prevents the `except` block from being executed, as it is designed to catch exceptions, not handle error messages returned as strings.

To address this, the `divide` function should raise a `ZeroDivisionError` when a division by zero is attempted. This will allow the `except` block in the `main` function to catch the exception and handle it appropriately. Here is the suggested modification to the `divide` function:

```python
def divide(a, b):
    if b == 0:
        raise ZeroDivisionError("Division by zero is not allowed.")
    return a / b
```

With this change, the `main` function will correctly catch the `ZeroDivisionError`, and the error message will be printed as expected. This aligns with standard Python practices for error handling and ensures that the code behaves as intended when a division by zero occurs.


--> Next agent: observer

Observer Agent Output:
ACTION: Analyze the provided code to identify any potential bugs or error conditions.

RESULT: The code contains a logical issue in the error handling mechanism within the `divide` function. Currently, when a division by zero is attempted, the function returns a string message instead of raising an exception. This behavior prevents the `except` block in the `main` function from executing, as it is designed to catch exceptions, not handle string messages. To align with standard Python practices and ensure proper error handling, the `divide` function should raise a `ZeroDivisionError` when `b` is zero. This change will allow the `main` function to catch the exception and execute the `except` block, providing a more robust and conventional error handling approach.

Suggested code modification:
```python
def divide(a, b):
    if b == 0:
        raise ZeroDivisionError("Division by zero is not allowed.")
    return a / b
```

This modification will ensure that the `main` function's `try-except` block operates as intended, catching the `ZeroDivisionError` and printing an appropriate error message.


--> Next agent: observer

Observer Agent Output:
ACTION: Analyze the provided code to identify any potential bugs or error conditions.

RESULT: Upon examining the code, the primary issue identified is with the error handling mechanism in the `divide` function. The function currently returns a string when a division by zero is attempted, which is not a standard practice in Python. This approach prevents the `except` block in the `main` function from executing as intended, as it is designed to catch exceptions, not handle string messages.

To adhere to standard Python practices and ensure proper exception handling, the `divide` function should raise a `ZeroDivisionError` instead of returning a string. This change will allow the `except` block in the `main` function to catch the exception and handle it appropriately.

Here is the suggested modification to the `divide` function:

```python
def divide(a, b):
    if b == 0:
        raise ZeroDivisionError("Division by zero is not allowed.")
    return a / b
```

With this modification, the `main` function will correctly catch the `ZeroDivisionError` and print the error message, ensuring the code behaves as expected when a division by zero is attempted.

Detected loop: observer agent called 4 times in a row without progress
Forcing transition to patcher to attempt a fix

--> Next agent: observer

Observer Agent Output:
ACTION: Analyze the provided code to identify any potential bugs or error conditions.

RESULT: Upon reviewing the code, the primary issue identified is with the error handling mechanism in the `divide` function. Currently, when a division by zero is attempted, the function returns a string message instead of raising an exception. This behavior prevents the `except` block in the `main` function from executing, as it is designed to catch exceptions, not handle string messages. To adhere to standard Python practices and ensure proper error handling, the `divide` function should raise a `ZeroDivisionError` when `b` is zero. This change will allow the `except` block in the `main` function to catch the exception and handle it appropriately. Here is the suggested modification:

```python
def divide(a, b):
    if b == 0:
        raise ZeroDivisionError("Division by zero is not allowed.")
    return a / b
```

With this modification, the code will correctly raise an exception for division by zero, allowing the `except` block to execute and print the error message. This approach aligns with Python's standard error handling practices.

Detected loop: observer agent called 4 times in a row without progress
Forcing transition to patcher to attempt a fix

--> Next agent: observer

Observer Agent Output:
ACTION: Analyze the provided code to identify any potential bugs or error conditions.

RESULT: The code contains a logical error in the way it handles division by zero. In the `divide` function, when `b` is zero, it returns a string "Error: Division by zero is not allowed." instead of raising an exception. This approach is inconsistent with standard Python practices, where a `ZeroDivisionError` should be raised to indicate an error condition. The current implementation will not trigger the `except` block in the `main` function, as it only catches exceptions, not string messages.

To align with standard error handling practices in Python, the `divide` function should raise a `ZeroDivisionError` when `b` is zero. This will allow the `except` block in the `main` function to catch the exception and handle it appropriately.

Suggested modification to the `divide` function:

```python
def divide(a, b):
    if b == 0:
        raise ZeroDivisionError("Division by zero is not allowed.")
    return a / b
```

This change will ensure that the division by zero is handled correctly by raising an exception, which can then be caught and managed in the `main` function's `except` block.

Detected loop: observer agent called 4 times in a row without progress
Forcing transition to patcher to attempt a fix

--> Next agent: observer

Observer Agent Output:
ACTION: Analyze the provided code to identify any potential bugs or error conditions.

RESULT: The code contains a logical error in the `divide` function's handling of division by zero. Currently, the function returns a string message when `b` is zero, which is not a standard practice in Python. Instead, it should raise a `ZeroDivisionError` to allow the exception handling mechanism in the `main` function to work correctly. This would align with Python's standard error handling practices and ensure that the `except` block can catch the exception and handle it appropriately. Here is the corrected version of the `divide` function:

```python
def divide(a, b):
    if b == 0:
        raise ZeroDivisionError("Division by zero is not allowed.")
    return a / b
```

With this change, the `main` function will catch the `ZeroDivisionError` and print the error message, maintaining consistency with Python's error handling conventions.

Detected loop: observer agent called 4 times in a row without progress
Forcing transition to patcher to attempt a fix

--> Next agent: observer

Observer Agent Output:
ACTION: Analyze the provided code to identify any potential bugs or error conditions.

RESULT: The code contains a logical error in the `divide` function. Currently, when a division by zero is attempted, the function returns a string message instead of raising an exception. This behavior is inconsistent with Python's standard error handling, where a `ZeroDivisionError` should be raised. This inconsistency can lead to unexpected behavior in the `main` function, as the exception handling block will not be triggered by the string return value.

To align with Python's standard practices and ensure proper exception handling, the `divide` function should be modified to raise a `ZeroDivisionError` when `b` is zero. This change will allow the `try-except` block in the `main` function to catch the exception and handle it appropriately.

Here is the suggested modification to the `divide` function:

```python
def divide(a, b):
    if b == 0:
        raise ZeroDivisionError("Division by zero is not allowed.")
    return a / b
```

With this change, the `main` function will correctly catch the `ZeroDivisionError` and print the error message, ensuring that the program behaves as expected when a division by zero is attempted.

Detected loop: observer agent called 4 times in a row without progress
Forcing transition to patcher to attempt a fix

--> Next agent: observer

Observer Agent Output:
ACTION: Analyze the provided code to identify any potential bugs or error conditions.

RESULT: Upon reviewing the code, the primary issue identified is the handling of division by zero within the `divide` function. Currently, the function returns a string message when a division by zero is attempted, which is not consistent with Python's standard error handling practices. Typically, Python raises a `ZeroDivisionError` exception in such cases. This inconsistency can lead to unexpected behavior, especially if the function is used in contexts where exceptions are expected for error handling.

To align with standard practices, the `divide` function should be modified to raise a `ZeroDivisionError` when `b` is zero. This change will ensure that the function behaves in a manner consistent with Python's built-in division operations, allowing for more predictable and standard error handling.

Suggested modification:
```python
def divide(a, b):
    if b == 0:
        raise ZeroDivisionError("division by zero")
    return a / b
```

This modification will allow the `main` function's `try-except` block to catch the `ZeroDivisionError` and handle it appropriately, maintaining consistency with typical Python error handling patterns.

Detected loop: observer agent called 4 times in a row without progress
Forcing transition to patcher to attempt a fix

--> Next agent: observer

Observer Agent Output:
ACTION: Analyze the provided code to identify any potential bugs or error conditions beyond the already identified issue with division by zero handling.

RESULT: Upon reviewing the code, the primary issue identified is the handling of division by zero within the `divide` function. The current implementation returns a string when `b` is zero, which is inconsistent with typical Python error handling practices. This inconsistency can lead to unexpected behavior if the caller expects a numerical result or an exception.

To align with Python's standard practices, the `divide` function should raise a `ZeroDivisionError` when `b` is zero. This allows the `try-except` block in the `main` function to catch and handle the error appropriately, maintaining consistency and clarity in error handling.

No other bugs or error conditions are evident in the provided code. The logic and structure appear sound, assuming the primary focus is on handling division operations.

Recommended modification:
```python
def divide(a, b):
    if b == 0:
        raise ZeroDivisionError("Division by zero is not allowed.")
    return a / b
```

This change will ensure that the `main` function's `try-except` block can effectively catch and handle the `ZeroDivisionError`, providing a more robust and standard error handling mechanism.

Detected loop: observer agent called 4 times in a row without progress
Forcing transition to patcher to attempt a fix

--> Next agent: observer

Observer Agent Output:
ACTION: Analyze the provided code to identify any potential bugs or error conditions, focusing on the handling of division by zero and any other possible issues.

RESULT: The primary issue in the code is the handling of division by zero within the `divide` function. Currently, the function returns a string when `b` is zero, which is inconsistent with Python's standard error handling practices. This inconsistency can lead to unexpected behavior, especially if the caller expects a numerical result or an exception.

To align with Python's standard practices, the `divide` function should raise a `ZeroDivisionError` when `b` is zero. This allows the `try-except` block in the `main` function to handle the error appropriately, maintaining consistency and clarity in error handling.

Additionally, there are no other apparent bugs or error conditions in the code. The logic is straightforward, and the use of a `try-except` block in the `main` function is appropriate for catching and handling exceptions.

Recommended modification:
```python
def divide(a, b):
    if b == 0:
        raise ZeroDivisionError("Division by zero is not allowed.")
    return a / b
```

This change will ensure that the `divide` function behaves consistently with Python's error handling conventions, allowing the `main` function to handle the exception as intended.

Detected loop: observer agent called 4 times in a row without progress
Forcing transition to patcher to attempt a fix

--> Next agent: observer

Observer Agent Output:
ACTION: Analyze the provided code to identify any potential bugs or error conditions, focusing on the handling of division by zero and the overall error management strategy.

RESULT: The code currently handles division by zero by returning a string error message from the `divide` function. This approach is unconventional in Python, where exceptions are typically used for error handling. The `divide` function should raise a `ZeroDivisionError` when `b` is zero, which is the standard practice in Python for handling such errors. This would allow the `try-except` block in the `main` function to catch the exception and handle it appropriately. By raising an exception, the code will be more consistent with Python's error handling conventions and will allow for more flexible error management in larger applications. The recommended modification is to replace the return statement with a `raise ZeroDivisionError("Division by zero is not allowed.")` when `b` is zero. This change will ensure that the error is handled in a manner consistent with Python's standard practices.

Detected loop: observer agent called 4 times in a row without progress
Forcing transition to patcher to attempt a fix

--> Next agent: observer

Observer Agent Output:
ACTION: Analyze the provided code to identify any potential bugs or error conditions beyond the already identified unconventional error handling in the `divide` function.

RESULT: Upon reviewing the code, the primary issue identified is the unconventional handling of division by zero in the `divide` function, which returns a string instead of raising an exception. This has already been addressed by recommending the use of a `ZeroDivisionError`. 

Additionally, the code does not contain any other apparent bugs or error conditions. The `try-except` block in the `main` function is correctly set up to catch exceptions, and the logic of the `divide` function is straightforward aside from the error handling method. 

To align with Python's standard practices, the `divide` function should be modified to raise a `ZeroDivisionError` when `b` is zero. This will allow the `try-except` block in the `main` function to handle the exception as intended. 

No further issues are detected in the current code structure. The next step is to implement the recommended change to raise an exception in the `divide` function.

Detected loop: observer agent called 4 times in a row without progress
Forcing transition to patcher to attempt a fix

--> Next agent: patcher

Patcher Agent Output:
ACTION: Modify the `divide` function to raise a `ZeroDivisionError` when `b` is zero, aligning with Python's standard error handling practices. This will allow the `try-except` block in the `main` function to handle the exception appropriately.

RESULT: The `divide` function has been updated to raise a `ZeroDivisionError` when division by zero is attempted. This change ensures that the code adheres to standard Python practices for error handling.

FIXED_CODE:
```python
# A simple script with a bug for Triangulum to find
def divide(a, b):
    if b == 0:
        raise ZeroDivisionError("Division by zero is not allowed.")
    return a / b

def main():
    try:
        result = divide(10, 0)  # Division by zero error
        print(f"Result: {result}")
    except ZeroDivisionError as e:
        print(f"Error: {e}")

if __name__ == "__main__":
    main()
```


Fixed code generated
Bug state updated: VERIFY
Bug escalated: Exceeded maximum iterations (15)

=== Debug cycle completed for Bug #1 (ESCALATE): Unknown bug ===


```

## Errors

```
Traceback (most recent call last):
  File "C:\Users\Yusuf\Downloads\Triangulum\triangulum_gpt.py", line 633, in <module>
    exit(main())
         ^^^^^^
  File "C:\Users\Yusuf\Downloads\Triangulum\triangulum_gpt.py", line 530, in main
    system.run_debug_cycle(bug, quiet=args.quiet)
  File "C:\Users\Yusuf\Downloads\Triangulum\triangulum_gpt.py", line 381, in run_debug_cycle
    print("\u26a0\ufe0f Bug escalated to human developers")
  File "C:\Users\Yusuf\AppData\Local\Programs\Python\Python312\Lib\encodings\cp1252.py", line 19, in encode
    return codecs.charmap_encode(input,self.errors,encoding_table)[0]
           ^^^^^^^^^^^^^^^^^^^^^^^^^^^^^^^^^^^^^^^^^^^^^^^^^^^^^^^
UnicodeEncodeError: 'charmap' codec can't encode characters in position 0-1: character maps to <undefined>

```

## Result

## Error

An error occurred during debugging: 'charmap' codec can't encode character '\u274c' in position 0: character maps to <undefined>
